Traceback (most recent call last):
  File "/home/bbc33/anaconda3/envs/pycuda/lib/python3.6/site-packages/numba/cuda/cudadrv/driver.py", line 495, in __getattr__
    code = DEVICE_ATTRIBUTES[attr]
KeyError: 'get_memory_info'

During handling of the above exception, another exception occurred:

Traceback (most recent call last):
  File "gpuinfo.py", line 35, in <module>
    print_gpu_info()
  File "gpuinfo.py", line 12, in print_gpu_info
    total_memory, free_memory = device.get_memory_info()
  File "/home/bbc33/anaconda3/envs/pycuda/lib/python3.6/site-packages/numba/cuda/cudadrv/driver.py", line 497, in __getattr__
    raise AttributeError(attr)
AttributeError: get_memory_info
