Traceback (most recent call last):
  File "/home/bbc33/anaconda3/envs/pycuda/lib/python3.6/site-packages/numba/cuda/cudadrv/driver.py", line 495, in __getattr__
    code = DEVICE_ATTRIBUTES[attr]
KeyError: 'total_memory'

During handling of the above exception, another exception occurred:

Traceback (most recent call last):
  File "gpuinfo.py", line 35, in <module>
    print_gpu_info()
  File "gpuinfo.py", line 10, in print_gpu_info
    print("Total global memory (GB):", device.total_memory / (1024 ** 3))
  File "/home/bbc33/anaconda3/envs/pycuda/lib/python3.6/site-packages/numba/cuda/cudadrv/driver.py", line 497, in __getattr__
    raise AttributeError(attr)
AttributeError: total_memory
