Traceback (most recent call last):
  File "gpuinfo.py", line 69, in <module>
    main()
  File "gpuinfo.py", line 56, in main
    elementwise_double[blocks_per_grid, threads_per_block](d_data)
  File "/home/bbc33/anaconda3/envs/pycuda/lib/python3.6/site-packages/numba/cuda/compiler.py", line 800, in __call__
    cfg(*args)
  File "/home/bbc33/anaconda3/envs/pycuda/lib/python3.6/site-packages/numba/cuda/compiler.py", line 536, in __call__
    sharedmem=self.sharedmem)
  File "/home/bbc33/anaconda3/envs/pycuda/lib/python3.6/site-packages/numba/cuda/compiler.py", line 610, in _kernel_call
    cu_func(*kernelargs)
  File "/home/bbc33/anaconda3/envs/pycuda/lib/python3.6/site-packages/numba/cuda/cudadrv/driver.py", line 1578, in __call__
    self.sharedmem, streamhandle, args)
  File "/home/bbc33/anaconda3/envs/pycuda/lib/python3.6/site-packages/numba/cuda/cudadrv/driver.py", line 1622, in launch_kernel
    None)
  File "/home/bbc33/anaconda3/envs/pycuda/lib/python3.6/site-packages/numba/cuda/cudadrv/driver.py", line 294, in safe_cuda_api_call
    self._check_error(fname, retcode)
  File "/home/bbc33/anaconda3/envs/pycuda/lib/python3.6/site-packages/numba/cuda/cudadrv/driver.py", line 329, in _check_error
    raise CudaAPIError(retcode, msg)
numba.cuda.cudadrv.driver.CudaAPIError: [1] Call to cuLaunchKernel results in CUDA_ERROR_INVALID_VALUE
