Traceback (most recent call last):
  File "/home/bbc33/anaconda3/envs/pycuda/lib/python3.6/site-packages/numba/cuda/cudadrv/driver.py", line 744, in _attempt_allocation
    allocator()
  File "/home/bbc33/anaconda3/envs/pycuda/lib/python3.6/site-packages/numba/cuda/cudadrv/driver.py", line 759, in allocator
    driver.cuMemAlloc(byref(ptr), bytesize)
  File "/home/bbc33/anaconda3/envs/pycuda/lib/python3.6/site-packages/numba/cuda/cudadrv/driver.py", line 294, in safe_cuda_api_call
    self._check_error(fname, retcode)
  File "/home/bbc33/anaconda3/envs/pycuda/lib/python3.6/site-packages/numba/cuda/cudadrv/driver.py", line 329, in _check_error
    raise CudaAPIError(retcode, msg)
numba.cuda.cudadrv.driver.CudaAPIError: [2] Call to cuMemAlloc results in CUDA_ERROR_OUT_OF_MEMORY

During handling of the above exception, another exception occurred:

Traceback (most recent call last):
  File "main.py", line 47, in <module>
    main()
  File "main.py", line 41, in main
    C = add_gpu(A, B)
  File "/home/bbc33/anaconda3/envs/pycuda/lib/python3.6/site-packages/numba/cuda/dispatcher.py", line 88, in __call__
    return CUDAUFuncMechanism.call(self.functions, args, kws)
  File "/home/bbc33/anaconda3/envs/pycuda/lib/python3.6/site-packages/numba/npyufunc/deviceufunc.py", line 301, in call
    devout = cr.device_array(shape, resty, stream=stream)
  File "/home/bbc33/anaconda3/envs/pycuda/lib/python3.6/site-packages/numba/cuda/dispatcher.py", line 215, in device_array
    return cuda.device_array(shape=shape, dtype=dtype, stream=stream)
  File "/home/bbc33/anaconda3/envs/pycuda/lib/python3.6/site-packages/numba/cuda/cudadrv/devices.py", line 225, in _require_cuda_context
    return fn(*args, **kws)
  File "/home/bbc33/anaconda3/envs/pycuda/lib/python3.6/site-packages/numba/cuda/api.py", line 127, in device_array
    stream=stream)
  File "/home/bbc33/anaconda3/envs/pycuda/lib/python3.6/site-packages/numba/cuda/cudadrv/devicearray.py", line 103, in __init__
    gpu_data = devices.get_context().memalloc(self.alloc_size)
  File "/home/bbc33/anaconda3/envs/pycuda/lib/python3.6/site-packages/numba/cuda/cudadrv/driver.py", line 761, in memalloc
    self._attempt_allocation(allocator)
  File "/home/bbc33/anaconda3/envs/pycuda/lib/python3.6/site-packages/numba/cuda/cudadrv/driver.py", line 751, in _attempt_allocation
    allocator()
  File "/home/bbc33/anaconda3/envs/pycuda/lib/python3.6/site-packages/numba/cuda/cudadrv/driver.py", line 759, in allocator
    driver.cuMemAlloc(byref(ptr), bytesize)
  File "/home/bbc33/anaconda3/envs/pycuda/lib/python3.6/site-packages/numba/cuda/cudadrv/driver.py", line 294, in safe_cuda_api_call
    self._check_error(fname, retcode)
  File "/home/bbc33/anaconda3/envs/pycuda/lib/python3.6/site-packages/numba/cuda/cudadrv/driver.py", line 329, in _check_error
    raise CudaAPIError(retcode, msg)
numba.cuda.cudadrv.driver.CudaAPIError: [2] Call to cuMemAlloc results in CUDA_ERROR_OUT_OF_MEMORY
