Traceback (most recent call last):
  File "main.py", line 100, in <module>
    main()
  File "main.py", line 84, in main
    tb_squares.test_all()
  File "/scratch/bbc33/pycuda/cuda/ex4/testbench.py", line 50, in test_all
    instance.run()
  File "/scratch/bbc33/pycuda/cuda/ex4/matmul.py", line 90, in run
    cuda.synchronize()
  File "/home/bbc33/anaconda3/envs/pycuda/lib/python3.6/site-packages/numba/cuda/api.py", line 199, in synchronize
    return current_context().synchronize()
  File "/home/bbc33/anaconda3/envs/pycuda/lib/python3.6/site-packages/numba/cuda/cudadrv/driver.py", line 911, in synchronize
    driver.cuCtxSynchronize()
  File "/home/bbc33/anaconda3/envs/pycuda/lib/python3.6/site-packages/numba/cuda/cudadrv/driver.py", line 294, in safe_cuda_api_call
    self._check_error(fname, retcode)
  File "/home/bbc33/anaconda3/envs/pycuda/lib/python3.6/site-packages/numba/cuda/cudadrv/driver.py", line 329, in _check_error
    raise CudaAPIError(retcode, msg)
numba.cuda.cudadrv.driver.CudaAPIError: [700] Call to cuCtxSynchronize results in UNKNOWN_CUDA_ERROR
Traceback (most recent call last):
  File "/home/bbc33/anaconda3/envs/pycuda/lib/python3.6/site-packages/numba/utils.py", line 754, in _exitfunc
    f()
  File "/home/bbc33/anaconda3/envs/pycuda/lib/python3.6/site-packages/numba/utils.py", line 678, in __call__
    return info.func(*info.args, **(info.kwargs or {}))
  File "/home/bbc33/anaconda3/envs/pycuda/lib/python3.6/site-packages/numba/cuda/cudadrv/driver.py", line 1385, in deref
    mem.free()
  File "/home/bbc33/anaconda3/envs/pycuda/lib/python3.6/site-packages/numba/cuda/cudadrv/driver.py", line 1271, in free
    self._finalizer()
  File "/home/bbc33/anaconda3/envs/pycuda/lib/python3.6/site-packages/numba/utils.py", line 678, in __call__
    return info.func(*info.args, **(info.kwargs or {}))
  File "/home/bbc33/anaconda3/envs/pycuda/lib/python3.6/site-packages/numba/cuda/cudadrv/driver.py", line 967, in core
    deallocations.add_item(driver.cuMemFree, handle, size)
  File "/home/bbc33/anaconda3/envs/pycuda/lib/python3.6/site-packages/numba/cuda/cudadrv/driver.py", line 599, in add_item
    self.clear()
  File "/home/bbc33/anaconda3/envs/pycuda/lib/python3.6/site-packages/numba/cuda/cudadrv/driver.py", line 610, in clear
    dtor(handle)
  File "/home/bbc33/anaconda3/envs/pycuda/lib/python3.6/site-packages/numba/cuda/cudadrv/driver.py", line 294, in safe_cuda_api_call
    self._check_error(fname, retcode)
  File "/home/bbc33/anaconda3/envs/pycuda/lib/python3.6/site-packages/numba/cuda/cudadrv/driver.py", line 329, in _check_error
    raise CudaAPIError(retcode, msg)
numba.cuda.cudadrv.driver.CudaAPIError: [700] Call to cuMemFree results in UNKNOWN_CUDA_ERROR
Traceback (most recent call last):
  File "/home/bbc33/anaconda3/envs/pycuda/lib/python3.6/site-packages/numba/utils.py", line 754, in _exitfunc
    f()
  File "/home/bbc33/anaconda3/envs/pycuda/lib/python3.6/site-packages/numba/utils.py", line 678, in __call__
    return info.func(*info.args, **(info.kwargs or {}))
  File "/home/bbc33/anaconda3/envs/pycuda/lib/python3.6/site-packages/numba/cuda/cudadrv/driver.py", line 1385, in deref
    mem.free()
  File "/home/bbc33/anaconda3/envs/pycuda/lib/python3.6/site-packages/numba/cuda/cudadrv/driver.py", line 1271, in free
    self._finalizer()
  File "/home/bbc33/anaconda3/envs/pycuda/lib/python3.6/site-packages/numba/utils.py", line 678, in __call__
    return info.func(*info.args, **(info.kwargs or {}))
  File "/home/bbc33/anaconda3/envs/pycuda/lib/python3.6/site-packages/numba/cuda/cudadrv/driver.py", line 967, in core
    deallocations.add_item(driver.cuMemFree, handle, size)
  File "/home/bbc33/anaconda3/envs/pycuda/lib/python3.6/site-packages/numba/cuda/cudadrv/driver.py", line 599, in add_item
    self.clear()
  File "/home/bbc33/anaconda3/envs/pycuda/lib/python3.6/site-packages/numba/cuda/cudadrv/driver.py", line 610, in clear
    dtor(handle)
  File "/home/bbc33/anaconda3/envs/pycuda/lib/python3.6/site-packages/numba/cuda/cudadrv/driver.py", line 294, in safe_cuda_api_call
    self._check_error(fname, retcode)
  File "/home/bbc33/anaconda3/envs/pycuda/lib/python3.6/site-packages/numba/cuda/cudadrv/driver.py", line 329, in _check_error
    raise CudaAPIError(retcode, msg)
numba.cuda.cudadrv.driver.CudaAPIError: [700] Call to cuMemFree results in UNKNOWN_CUDA_ERROR
Traceback (most recent call last):
  File "/home/bbc33/anaconda3/envs/pycuda/lib/python3.6/site-packages/numba/utils.py", line 754, in _exitfunc
    f()
  File "/home/bbc33/anaconda3/envs/pycuda/lib/python3.6/site-packages/numba/utils.py", line 678, in __call__
    return info.func(*info.args, **(info.kwargs or {}))
  File "/home/bbc33/anaconda3/envs/pycuda/lib/python3.6/site-packages/numba/cuda/cudadrv/driver.py", line 1046, in core
    dealloc.add_item(module_unload, handle)
  File "/home/bbc33/anaconda3/envs/pycuda/lib/python3.6/site-packages/numba/cuda/cudadrv/driver.py", line 599, in add_item
    self.clear()
  File "/home/bbc33/anaconda3/envs/pycuda/lib/python3.6/site-packages/numba/cuda/cudadrv/driver.py", line 610, in clear
    dtor(handle)
  File "/home/bbc33/anaconda3/envs/pycuda/lib/python3.6/site-packages/numba/cuda/cudadrv/driver.py", line 294, in safe_cuda_api_call
    self._check_error(fname, retcode)
  File "/home/bbc33/anaconda3/envs/pycuda/lib/python3.6/site-packages/numba/cuda/cudadrv/driver.py", line 329, in _check_error
    raise CudaAPIError(retcode, msg)
numba.cuda.cudadrv.driver.CudaAPIError: [700] Call to cuMemFree results in UNKNOWN_CUDA_ERROR
